Workbook

Sheet Asosiy
A1: Last Articul: | B1: 404 | M1: =SUM(O3:O31) -> 410 | Q1: =SUM(S3:S31) -> 61500000 | R1: =SUM(T3:T31) -> 71750000 | V1: 34 | W1: 1 | Z1: 2 | AA1: 3 | AB1: 4 | AE1: 5 | AF1: 6 | AH1: 7 | AI1: 8 | AJ1: 9 | AK1: 10 | AL1: 11 | AO1: 12 | AR1: 13 | AS1: 14 | AT1: 15 | AX1: 16 | AZ1: 17 | BA1: 18 | BC1: 19 | BD1: 20 | BE1: 21 | BH1: 22 | BI1: 23 | BL1: 24 | BM1: 25 | BP1: 26 | BQ1: 27 | BS1: 28 | BV1: 29 | BX1: 30 | BY1: 31 | CA1: 32 | CB1: 33
A2: Модель | B2: Образец | C2: Варианты | D2: Вид товара | E2: Категория | F2: Группы | G2: Код модели | H2: Бренд | I2: Коллекция | J2: Сезон | K2: Размерный ряд | L2: Описание | M2: Наименование | N2: Серия | O2: Количество | P2: Закупочная цена | Q2: Надценка | R2: Цена продажи | S2: Сумма закупа | T2: Сумма продажи | U2: Тест | V2: Multicolor | W2: Beyaz | X2: Vizon-Ekru | Y2: Caramel | Z2: Ekru | AA2: Beige | AB2: Sari | AC2: Keten | AD2: K.laci-Kiremit | AE2: Kiremit | AF2: Bordo | AG2: Bordo K.Laci | AH2: K.Bordo | AI2: Pink | AJ2: Violet | AK2: A.Yesil | AL2: Yesil | AM2: P.Yesil-Siyah | AN2: K.Laci.P.Yesil | AO2: P.Yesil | AP2: A.Haki | AQ2: M.Petrol | AR2: Haki | AS2: Mint | AT2: Turkuaz | AU2: A.Mavi | AV2: P.Mavi.Melan | AW2: Petrol.Mavi | AX2: Mavi | AY2: Kirmizi | AZ2: Lacivert | BA2: Indigo | BB2: K.Laci-Indigo | BC2: K.Lacivert | BD2: GRI | BE2: K.GRI | BF2: Haki.Kahva | BG2: K.Kahve.Kahve | BH2: Kahve | BI2: K.Kahve | BJ2: K.Laci.Kahve | BK2: Kahvamel | BL2: A.Lacivert | BM2: K.Indigo | BN2: Sax | BO2: K.Taba | BP2: Taba | BQ2: Vizon | BR2: Vizon.K.Kahve | BS2: K.Vizon | BT2: Kum.Bej | BU2: K.Bej.Ekru | BV2: K.Bej | BW2: A.Bej.Ekru | BX2: A.Bej | BY2: Antrasit | BZ2: A.Kiremit | CA2: K.Kiremit | CB2: Siyah
A3: =IF(F3="","",_xlfn.CONCAT(_xlfn.IFNA(VLOOKUP(I3,Ruyxat!$F$2:$G$6,2,0),""),_xlfn.IFNA(VLOOKUP(F3,Ruyxat!$T$2:$U$16,2,0),""),TEXT($B$1+1,"00000"))) -> A26TOP00405 | C3: =Ruyxat!B23 -> Блузка | D3: Свитер | E3: Свитеры и кардиганы | F3: Одежда Топ | G3: 1M21241-1587 | H3: LIWALI | I3: AW26 | J3: Весна-Осень | K3: M-3XL | L3: варот замок мадел | M3: =IF(D3="","",TRIM(D3&" "&L3&" "&H3&" "&G3)) -> Свитер варот замок мадел LIWALI 1M21241-1587 | N3: 5 | O3: 120 | P3: 150000 | Q3: 0.2 | R3: 175000 | S3: =IF($O3="","",$O3*$P3) -> 18000000 | T3: =IF($O3="","",$O3*$R3) -> 21000000 | U3: =IF($O3="","",IF($O3=SUM($V3:$CB3),"OK","ERROR")) -> OK | AH3: 30 | BC3: 55 | BI3: 6 | CB3: 29
A4: =IF(F4="","",_xlfn.CONCAT(_xlfn.IFNA(VLOOKUP(I4,Ruyxat!$F$2:$G$6,2,0),""),_xlfn.IFNA(VLOOKUP(F4,Ruyxat!$T$2:$U$16,2,0),""),TEXT(MID(A3,7,5)+1,"00000"))) -> A26TOP00406 | B4: 2 | C4: =Ruyxat!B24 -> Кофта | D4: Свитер | E4: =_xlfn.IFNA(VLOOKUP(D4,[1]Ruyxat!$J$2:$L$601,2,0),"") -> Свитеры и кардиганы | F4: =_xlfn.IFNA(VLOOKUP(D4,[1]Ruyxat!$J$2:$L$601,3,0),"") -> Одежда Топ | G4: 1M21241-1485 | H4: LIWALI | I4: AW26 | J4: Весна-Осень | K4: M-3XL | L4: варот замок мелани | M4: =IF(D4="","",TRIM(D4&" "&L4&" "&H4&" "&G4)) -> Свитер варот замок мелани LIWALI 1M21241-1485 | N4: 5 | O4: 290 | P4: 150000 | Q4: 0.2 | R4: 175000 | S4: =IF($O4="","",$O4*$P4) -> 43500000 | T4: =IF($O4="","",$O4*$R4) -> 50750000 | U4: =IF($O4="","",IF($O4=SUM($V4:$CB4),"OK","ERROR")) -> OK | AN4: 26 | BB4: 127 | BG4: 27 | BJ4: 52 | BR4: 30 | BU4: 28
A5: =IF(F5="","",_xlfn.CONCAT(_xlfn.IFNA(VLOOKUP(I5,Ruyxat!$F$2:$G$6,2,0),""),_xlfn.IFNA(VLOOKUP(F5,Ruyxat!$T$2:$U$16,2,0),""),TEXT(MID(A4,7,5)+1,"00000"))) | B5: 3 | C5: =Ruyxat!B59 -> Туника | E5: =_xlfn.IFNA(VLOOKUP(D5,[1]Ruyxat!$J$2:$L$601,2,0),"") | F5: =_xlfn.IFNA(VLOOKUP(D5,[1]Ruyxat!$J$2:$L$601,3,0),"") | M5: =IF(D5="","",TRIM(D5&" "&L5&" "&H5&" "&G5)) | S5: =IF($O5="","",$O5*$P5) | T5: =IF($O5="","",$O5*$R5) | U5: =IF($O5="","",IF($O5=SUM($V5:$CB5),"OK","ERROR"))
A6: =IF(F6="","",_xlfn.CONCAT(_xlfn.IFNA(VLOOKUP(I6,Ruyxat!$F$2:$G$6,2,0),""),_xlfn.IFNA(VLOOKUP(F6,Ruyxat!$T$2:$U$16,2,0),""),TEXT(MID(A5,7,5)+1,"00000"))) | B6: 4 | C6: =Ruyxat!B60 -> Платье | E6: =_xlfn.IFNA(VLOOKUP(D6,[1]Ruyxat!$J$2:$L$601,2,0),"") | F6: =_xlfn.IFNA(VLOOKUP(D6,[1]Ruyxat!$J$2:$L$601,3,0),"") | M6: =IF(D6="","",TRIM(D6&" "&L6&" "&H6&" "&G6)) | P6: 0 | R6: =IF($O6="","",ROUND($P6*(1+$Q6),-3)) | S6: =IF($O6="","",$O6*$P6) | T6: =IF($O6="","",$O6*$R6) | U6: =IF($O6="","",IF($O6=SUM($V6:$CB6),"OK","ERROR"))
A7: =IF(F7="","",_xlfn.CONCAT(_xlfn.IFNA(VLOOKUP(I7,Ruyxat!$F$2:$G$6,2,0),""),_xlfn.IFNA(VLOOKUP(F7,Ruyxat!$T$2:$U$16,2,0),""),TEXT(MID(A6,7,5)+1,"00000"))) | B7: 5 | C7: =Ruyxat!B61 -> Сарафан | E7: =_xlfn.IFNA(VLOOKUP(D7,[1]Ruyxat!$J$2:$L$601,2,0),"") | F7: =_xlfn.IFNA(VLOOKUP(D7,[1]Ruyxat!$J$2:$L$601,3,0),"") | M7: =IF(D7="","",TRIM(D7&" "&L7&" "&H7&" "&G7)) | P7: 0 | R7: =IF($O7="","",ROUND($P7*(1+$Q7),-3)) | S7: =IF($O7="","",$O7*$P7) | T7: =IF($O7="","",$O7*$R7) | U7: =IF($O7="","",IF($O7=SUM($V7:$CB7),"OK","ERROR"))
A8: =IF(F8="","",_xlfn.CONCAT(_xlfn.IFNA(VLOOKUP(I8,Ruyxat!$F$2:$G$6,2,0),""),_xlfn.IFNA(VLOOKUP(F8,Ruyxat!$T$2:$U$16,2,0),""),TEXT(MID(A7,7,5)+1,"00000"))) | B8: 6 | C8: =Ruyxat!B62 -> Рубашка | E8: =_xlfn.IFNA(VLOOKUP(D8,[1]Ruyxat!$J$2:$L$601,2,0),"") | F8: =_xlfn.IFNA(VLOOKUP(D8,[1]Ruyxat!$J$2:$L$601,3,0),"") | M8: =IF(D8="","",TRIM(D8&" "&L8&" "&H8&" "&G8)) | P8: 0 | R8: =IF($O8="","",ROUND($P8*(1+$Q8),-3)) | S8: =IF($O8="","",$O8*$P8) | T8: =IF($O8="","",$O8*$R8) | U8: =IF($O8="","",IF($O8=SUM($V8:$CB8),"OK","ERROR"))
A9: =IF(F9="","",_xlfn.CONCAT(_xlfn.IFNA(VLOOKUP(I9,Ruyxat!$F$2:$G$6,2,0),""),_xlfn.IFNA(VLOOKUP(F9,Ruyxat!$T$2:$U$16,2,0),""),TEXT(MID(A8,7,5)+1,"00000"))) | B9: 7 | C9: =Ruyxat!B63 -> Рубашка с длинными рукавами | E9: =_xlfn.IFNA(VLOOKUP(D9,[1]Ruyxat!$J$2:$L$601,2,0),"") | F9: =_xlfn.IFNA(VLOOKUP(D9,[1]Ruyxat!$J$2:$L$601,3,0),"") | M9: =IF(D9="","",TRIM(D9&" "&L9&" "&H9&" "&G9)) | P9: 0 | R9: =IF($O9="","",ROUND($P9*(1+$Q9),-3)) | S9: =IF($O9="","",$O9*$P9) | T9: =IF($O9="","",$O9*$R9) | U9: =IF($O9="","",IF($O9=SUM($V9:$CB9),"OK","ERROR"))
A10: =IF(F10="","",_xlfn.CONCAT(_xlfn.IFNA(VLOOKUP(I10,Ruyxat!$F$2:$G$6,2,0),""),_xlfn.IFNA(VLOOKUP(F10,Ruyxat!$T$2:$U$16,2,0),""),TEXT(MID(A9,7,5)+1,"00000"))) | B10: 8 | C10: =Ruyxat!B64 -> Водолазка | E10: =_xlfn.IFNA(VLOOKUP(D10,[1]Ruyxat!$J$2:$L$601,2,0),"") | F10: =_xlfn.IFNA(VLOOKUP(D10,[1]Ruyxat!$J$2:$L$601,3,0),"") | M10: =IF(D10="","",TRIM(D10&" "&L10&" "&H10&" "&G10)) | P10: 0 | R10: =IF($O10="","",ROUND($P10*(1+$Q10),-3)) | S10: =IF($O10="","",$O10*$P10) | T10: =IF($O10="","",$O10*$R10) | U10: =IF($O10="","",IF($O10=SUM($V10:$CB10),"OK","ERROR"))
A11: =IF(F11="","",_xlfn.CONCAT(_xlfn.IFNA(VLOOKUP(I11,Ruyxat!$F$2:$G$6,2,0),""),_xlfn.IFNA(VLOOKUP(F11,Ruyxat!$T$2:$U$16,2,0),""),TEXT(MID(A10,7,5)+1,"00000"))) | B11: 9 | C11: =Ruyxat!B65 -> Джемпер | E11: =_xlfn.IFNA(VLOOKUP(D11,[1]Ruyxat!$J$2:$L$601,2,0),"") | F11: =_xlfn.IFNA(VLOOKUP(D11,[1]Ruyxat!$J$2:$L$601,3,0),"") | M11: =IF(D11="","",TRIM(D11&" "&L11&" "&H11&" "&G11)) | P11: 0 | R11: =IF($O11="","",ROUND($P11*(1+$Q11),-3)) | S11: =IF($O11="","",$O11*$P11) | T11: =IF($O11="","",$O11*$R11) | U11: =IF($O11="","",IF($O11=SUM($V11:$CB11),"OK","ERROR"))
A12: =IF(F12="","",_xlfn.CONCAT(_xlfn.IFNA(VLOOKUP(I12,Ruyxat!$F$2:$G$6,2,0),""),_xlfn.IFNA(VLOOKUP(F12,Ruyxat!$T$2:$U$16,2,0),""),TEXT(MID(A11,7,5)+1,"00000"))) | B12: 10 | C12: =Ruyxat!B66 -> Кардиган | E12: =_xlfn.IFNA(VLOOKUP(D12,[1]Ruyxat!$J$2:$L$601,2,0),"") | F12: =_xlfn.IFNA(VLOOKUP(D12,[1]Ruyxat!$J$2:$L$601,3,0),"") | M12: =IF(D12="","",TRIM(D12&" "&L12&" "&H12&" "&G12)) | P12: 0 | R12: =IF($O12="","",ROUND($P12*(1+$Q12),-3)) | S12: =IF($O12="","",$O12*$P12) | T12: =IF($O12="","",$O12*$R12) | U12: =IF($O12="","",IF($O12=SUM($V12:$CB12),"OK","ERROR"))
A13: =IF(F13="","",_xlfn.CONCAT(_xlfn.IFNA(VLOOKUP(I13,Ruyxat!$F$2:$G$6,2,0),""),_xlfn.IFNA(VLOOKUP(F13,Ruyxat!$T$2:$U$16,2,0),""),TEXT(MID(A12,7,5)+1,"00000"))) | B13: 11 | C13: =Ruyxat!B67 -> Пуловер | E13: =_xlfn.IFNA(VLOOKUP(D13,[1]Ruyxat!$J$2:$L$601,2,0),"") | F13: =_xlfn.IFNA(VLOOKUP(D13,[1]Ruyxat!$J$2:$L$601,3,0),"") | M13: =IF(D13="","",TRIM(D13&" "&L13&" "&H13&" "&G13)) | P13: 0 | R13: =IF($O13="","",ROUND($P13*(1+$Q13),-3)) | S13: =IF($O13="","",$O13*$P13) | T13: =IF($O13="","",$O13*$R13) | U13: =IF($O13="","",IF($O13=SUM($V13:$CB13),"OK","ERROR"))
A14: =IF(F14="","",_xlfn.CONCAT(_xlfn.IFNA(VLOOKUP(I14,Ruyxat!$F$2:$G$6,2,0),""),_xlfn.IFNA(VLOOKUP(F14,Ruyxat!$T$2:$U$16,2,0),""),TEXT(MID(A13,7,5)+1,"00000"))) | B14: 12 | C14: =Ruyxat!B68 -> Свитер | E14: =_xlfn.IFNA(VLOOKUP(D14,[1]Ruyxat!$J$2:$L$601,2,0),"") | F14: =_xlfn.IFNA(VLOOKUP(D14,[1]Ruyxat!$J$2:$L$601,3,0),"") | M14: =IF(D14="","",TRIM(D14&" "&L14&" "&H14&" "&G14)) | P14: 0 | R14: =IF($O14="","",ROUND($P14*(1+$Q14),-3)) | S14: =IF($O14="","",$O14*$P14) | T14: =IF($O14="","",$O14*$R14) | U14: =IF($O14="","",IF($O14=SUM($V14:$CB14),"OK","ERROR"))
A15: =IF(F15="","",_xlfn.CONCAT(_xlfn.IFNA(VLOOKUP(I15,Ruyxat!$F$2:$G$6,2,0),""),_xlfn.IFNA(VLOOKUP(F15,Ruyxat!$T$2:$U$16,2,0),""),TEXT(MID(A14,7,5)+1,"00000"))) | B15: 13 | C15: =Ruyxat!B69 -> Свитер жилетка | E15: =_xlfn.IFNA(VLOOKUP(D15,[1]Ruyxat!$J$2:$L$601,2,0),"") | F15: =_xlfn.IFNA(VLOOKUP(D15,[1]Ruyxat!$J$2:$L$601,3,0),"") | M15: =IF(D15="","",TRIM(D15&" "&L15&" "&H15&" "&G15)) | P15: 0 | R15: =IF($O15="","",ROUND($P15*(1+$Q15),-3)) | S15: =IF($O15="","",$O15*$P15) | T15: =IF($O15="","",$O15*$R15) | U15: =IF($O15="","",IF($O15=SUM($V15:$CB15),"OK","ERROR"))
A16: =IF(F16="","",_xlfn.CONCAT(_xlfn.IFNA(VLOOKUP(I16,Ruyxat!$F$2:$G$6,2,0),""),_xlfn.IFNA(VLOOKUP(F16,Ruyxat!$T$2:$U$16,2,0),""),TEXT(MID(A15,7,5)+1,"00000"))) | B16: 14 | C16: =Ruyxat!B70 -> Свитер поло | E16: =_xlfn.IFNA(VLOOKUP(D16,[1]Ruyxat!$J$2:$L$601,2,0),"") | F16: =_xlfn.IFNA(VLOOKUP(D16,[1]Ruyxat!$J$2:$L$601,3,0),"") | M16: =IF(D16="","",TRIM(D16&" "&L16&" "&H16&" "&G16)) | P16: 0 | R16: =IF($O16="","",ROUND($P16*(1+$Q16),-3)) | S16: =IF($O16="","",$O16*$P16) | T16: =IF($O16="","",$O16*$R16) | U16: =IF($O16="","",IF($O16=SUM($V16:$CB16),"OK","ERROR"))
A17: =IF(F17="","",_xlfn.CONCAT(_xlfn.IFNA(VLOOKUP(I17,Ruyxat!$F$2:$G$6,2,0),""),_xlfn.IFNA(VLOOKUP(F17,Ruyxat!$T$2:$U$16,2,0),""),TEXT(MID(A16,7,5)+1,"00000"))) | B17: 15 | C17: =Ruyxat!B71 -> Американка | E17: =_xlfn.IFNA(VLOOKUP(D17,[1]Ruyxat!$J$2:$L$601,2,0),"") | F17: =_xlfn.IFNA(VLOOKUP(D17,[1]Ruyxat!$J$2:$L$601,3,0),"") | M17: =IF(D17="","",TRIM(D17&" "&L17&" "&H17&" "&G17)) | P17: 0 | R17: =IF($O17="","",ROUND($P17*(1+$Q17),-3)) | S17: =IF($O17="","",$O17*$P17) | T17: =IF($O17="","",$O17*$R17) | U17: =IF($O17="","",IF($O17=SUM($V17:$CB17),"OK","ERROR"))
A18: =IF(F18="","",_xlfn.CONCAT(_xlfn.IFNA(VLOOKUP(I18,Ruyxat!$F$2:$G$6,2,0),""),_xlfn.IFNA(VLOOKUP(F18,Ruyxat!$T$2:$U$16,2,0),""),TEXT(MID(A17,7,5)+1,"00000"))) | B18: 16 | C18: =Ruyxat!B72 -> Олимпийка | E18: =_xlfn.IFNA(VLOOKUP(D18,[1]Ruyxat!$J$2:$L$601,2,0),"") | F18: =_xlfn.IFNA(VLOOKUP(D18,[1]Ruyxat!$J$2:$L$601,3,0),"") | M18: =IF(D18="","",TRIM(D18&" "&L18&" "&H18&" "&G18)) | P18: 0 | R18: =IF($O18="","",ROUND($P18*(1+$Q18),-3)) | S18: =IF($O18="","",$O18*$P18) | T18: =IF($O18="","",$O18*$R18) | U18: =IF($O18="","",IF($O18=SUM($V18:$CB18),"OK","ERROR"))
A19: =IF(F19="","",_xlfn.CONCAT(_xlfn.IFNA(VLOOKUP(I19,Ruyxat!$F$2:$G$6,2,0),""),_xlfn.IFNA(VLOOKUP(F19,Ruyxat!$T$2:$U$16,2,0),""),TEXT(MID(A18,7,5)+1,"00000"))) | B19: 17 | C19: =Ruyxat!B73 -> Толстовка | E19: =_xlfn.IFNA(VLOOKUP(D19,[1]Ruyxat!$J$2:$L$601,2,0),"") | F19: =_xlfn.IFNA(VLOOKUP(D19,[1]Ruyxat!$J$2:$L$601,3,0),"") | M19: =IF(D19="","",TRIM(D19&" "&L19&" "&H19&" "&G19)) | R19: =IF($O19="","",ROUND($P19*(1+$Q19),-3)) | S19: =IF($O19="","",$O19*$P19) | T19: =IF($O19="","",$O19*$R19) | U19: =IF($O19="","",IF($O19=SUM($V19:$CB19),"OK","ERROR"))
A20: =IF(F20="","",_xlfn.CONCAT(_xlfn.IFNA(VLOOKUP(I20,Ruyxat!$F$2:$G$6,2,0),""),_xlfn.IFNA(VLOOKUP(F20,Ruyxat!$T$2:$U$16,2,0),""),TEXT(MID(A19,7,5)+1,"00000"))) | B20: 18 | C20: =Ruyxat!B74 -> Худи | E20: =_xlfn.IFNA(VLOOKUP(D20,[1]Ruyxat!$J$2:$L$601,2,0),"") | F20: =_xlfn.IFNA(VLOOKUP(D20,[1]Ruyxat!$J$2:$L$601,3,0),"") | M20: =IF(D20="","",TRIM(D20&" "&L20&" "&H20&" "&G20)) | R20: =IF($O20="","",ROUND($P20*(1+$Q20),-3)) | S20: =IF($O20="","",$O20*$P20) | T20: =IF($O20="","",$O20*$R20) | U20: =IF($O20="","",IF($O20=SUM($V20:$CB20),"OK","ERROR"))
A21: =IF(F21="","",_xlfn.CONCAT(_xlfn.IFNA(VLOOKUP(I21,Ruyxat!$F$2:$G$6,2,0),""),_xlfn.IFNA(VLOOKUP(F21,Ruyxat!$T$2:$U$16,2,0),""),TEXT(MID(A20,7,5)+1,"00000"))) | B21: 19 | C21: =Ruyxat!B75 -> Лонгслив | E21: =_xlfn.IFNA(VLOOKUP(D21,[1]Ruyxat!$J$2:$L$601,2,0),"") | F21: =_xlfn.IFNA(VLOOKUP(D21,[1]Ruyxat!$J$2:$L$601,3,0),"") | M21: =IF(D21="","",TRIM(D21&" "&L21&" "&H21&" "&G21)) | R21: =IF($O21="","",ROUND($P21*(1+$Q21),-3)) | S21: =IF($O21="","",$O21*$P21) | T21: =IF($O21="","",$O21*$R21) | U21: =IF($O21="","",IF($O21=SUM($V21:$CB21),"OK","ERROR"))
A22: =IF(F22="","",_xlfn.CONCAT(_xlfn.IFNA(VLOOKUP(I22,Ruyxat!$F$2:$G$6,2,0),""),_xlfn.IFNA(VLOOKUP(F22,Ruyxat!$T$2:$U$16,2,0),""),TEXT(MID(A21,7,5)+1,"00000"))) | B22: 20 | C22: =Ruyxat!B76 -> Футболка поло | E22: =_xlfn.IFNA(VLOOKUP(D22,[1]Ruyxat!$J$2:$L$601,2,0),"") | F22: =_xlfn.IFNA(VLOOKUP(D22,[1]Ruyxat!$J$2:$L$601,3,0),"") | M22: =IF(D22="","",TRIM(D22&" "&L22&" "&H22&" "&G22)) | R22: =IF($O22="","",ROUND($P22*(1+$Q22),-3)) | S22: =IF($O22="","",$O22*$P22) | T22: =IF($O22="","",$O22*$R22) | U22: =IF($O22="","",IF($O22=SUM($V22:$CB22),"OK","ERROR"))
A23: =IF(F23="","",_xlfn.CONCAT(_xlfn.IFNA(VLOOKUP(I23,Ruyxat!$F$2:$G$6,2,0),""),_xlfn.IFNA(VLOOKUP(F23,Ruyxat!$T$2:$U$16,2,0),""),TEXT(MID(A22,7,5)+1,"00000"))) | B23: 21 | C23: =Ruyxat!B77 -> Поло с длинными рукавами | E23: =_xlfn.IFNA(VLOOKUP(D23,[1]Ruyxat!$J$2:$L$601,2,0),"") | F23: =_xlfn.IFNA(VLOOKUP(D23,[1]Ruyxat!$J$2:$L$601,3,0),"") | M23: =IF(D23="","",TRIM(D23&" "&L23&" "&H23&" "&G23)) | R23: =IF($O23="","",ROUND($P23*(1+$Q23),-3)) | S23: =IF($O23="","",$O23*$P23) | T23: =IF($O23="","",$O23*$R23) | U23: =IF($O23="","",IF($O23=SUM($V23:$CB23),"OK","ERROR"))
A24: =IF(F24="","",_xlfn.CONCAT(_xlfn.IFNA(VLOOKUP(I24,Ruyxat!$F$2:$G$6,2,0),""),_xlfn.IFNA(VLOOKUP(F24,Ruyxat!$T$2:$U$16,2,0),""),TEXT(MID(A23,7,5)+1,"00000"))) | B24: 22 | C24: =Ruyxat!B78 -> Футболка | E24: =_xlfn.IFNA(VLOOKUP(D24,[1]Ruyxat!$J$2:$L$601,2,0),"") | F24: =_xlfn.IFNA(VLOOKUP(D24,[1]Ruyxat!$J$2:$L$601,3,0),"") | M24: =IF(D24="","",TRIM(D24&" "&L24&" "&H24&" "&G24)) | R24: =IF($O24="","",ROUND($P24*(1+$Q24),-3)) | S24: =IF($O24="","",$O24*$P24) | T24: =IF($O24="","",$O24*$R24) | U24: =IF($O24="","",IF($O24=SUM($V24:$CB24),"OK","ERROR"))
A25: =IF(F25="","",_xlfn.CONCAT(_xlfn.IFNA(VLOOKUP(I25,Ruyxat!$F$2:$G$6,2,0),""),_xlfn.IFNA(VLOOKUP(F25,Ruyxat!$T$2:$U$16,2,0),""),TEXT(MID(A24,7,5)+1,"00000"))) | B25: 23 | C25: =Ruyxat!B79 -> Футболка безрукавка | E25: =_xlfn.IFNA(VLOOKUP(D25,[1]Ruyxat!$J$2:$L$601,2,0),"") | F25: =_xlfn.IFNA(VLOOKUP(D25,[1]Ruyxat!$J$2:$L$601,3,0),"") | M25: =IF(D25="","",TRIM(D25&" "&L25&" "&H25&" "&G25)) | R25: =IF($O25="","",ROUND($P25*(1+$Q25),-3)) | S25: =IF($O25="","",$O25*$P25) | T25: =IF($O25="","",$O25*$R25) | U25: =IF($O25="","",IF($O25=SUM($V25:$CB25),"OK","ERROR"))
A26: =IF(F26="","",_xlfn.CONCAT(_xlfn.IFNA(VLOOKUP(I26,Ruyxat!$F$2:$G$6,2,0),""),_xlfn.IFNA(VLOOKUP(F26,Ruyxat!$T$2:$U$16,2,0),""),TEXT(MID(A25,7,5)+1,"00000"))) | B26: 24 | C26: =Ruyxat!B80 -> Футболка поло с д.р | E26: =_xlfn.IFNA(VLOOKUP(D26,[1]Ruyxat!$J$2:$L$601,2,0),"") | F26: =_xlfn.IFNA(VLOOKUP(D26,[1]Ruyxat!$J$2:$L$601,3,0),"") | M26: =IF(D26="","",TRIM(D26&" "&L26&" "&H26&" "&G26)) | R26: =IF($O26="","",ROUND($P26*(1+$Q26),-3)) | S26: =IF($O26="","",$O26*$P26) | T26: =IF($O26="","",$O26*$R26) | U26: =IF($O26="","",IF($O26=SUM($V26:$CB26),"OK","ERROR"))
A27: =IF(F27="","",_xlfn.CONCAT(_xlfn.IFNA(VLOOKUP(I27,Ruyxat!$F$2:$G$6,2,0),""),_xlfn.IFNA(VLOOKUP(F27,Ruyxat!$T$2:$U$16,2,0),""),TEXT(MID(A26,7,5)+1,"00000"))) | B27: 25 | C27: =Ruyxat!B81 -> Блузка и юбка | E27: =_xlfn.IFNA(VLOOKUP(D27,[1]Ruyxat!$J$2:$L$601,2,0),"") | F27: =_xlfn.IFNA(VLOOKUP(D27,[1]Ruyxat!$J$2:$L$601,3,0),"") | M27: =IF(D27="","",TRIM(D27&" "&L27&" "&H27&" "&G27)) | R27: =IF($O27="","",ROUND($P27*(1+$Q27),-3)) | S27: =IF($O27="","",$O27*$P27) | T27: =IF($O27="","",$O27*$R27) | U27: =IF($O27="","",IF($O27=SUM($V27:$CB27),"OK","ERROR"))
A28: =IF(F28="","",_xlfn.CONCAT(_xlfn.IFNA(VLOOKUP(I28,Ruyxat!$F$2:$G$6,2,0),""),_xlfn.IFNA(VLOOKUP(F28,Ruyxat!$T$2:$U$16,2,0),""),TEXT(MID(A27,7,5)+1,"00000"))) | B28: 26 | C28: =Ruyxat!B82 -> Боди и штаны | E28: =_xlfn.IFNA(VLOOKUP(D28,[1]Ruyxat!$J$2:$L$601,2,0),"") | F28: =_xlfn.IFNA(VLOOKUP(D28,[1]Ruyxat!$J$2:$L$601,3,0),"") | M28: =IF(D28="","",TRIM(D28&" "&L28&" "&H28&" "&G28)) | R28: =IF($O28="","",ROUND($P28*(1+$Q28),-3)) | S28: =IF($O28="","",$O28*$P28) | T28: =IF($O28="","",$O28*$R28) | U28: =IF($O28="","",IF($O28=SUM($V28:$CB28),"OK","ERROR"))
A29: =IF(F29="","",_xlfn.CONCAT(_xlfn.IFNA(VLOOKUP(I29,Ruyxat!$F$2:$G$6,2,0),""),_xlfn.IFNA(VLOOKUP(F29,Ruyxat!$T$2:$U$16,2,0),""),TEXT(MID(A28,7,5)+1,"00000"))) | B29: 27 | C29: =Ruyxat!B83 -> Ветровка и штаны | E29: =_xlfn.IFNA(VLOOKUP(D29,[1]Ruyxat!$J$2:$L$601,2,0),"") | F29: =_xlfn.IFNA(VLOOKUP(D29,[1]Ruyxat!$J$2:$L$601,3,0),"") | M29: =IF(D29="","",TRIM(D29&" "&L29&" "&H29&" "&G29)) | R29: =IF($O29="","",ROUND($P29*(1+$Q29),-3)) | S29: =IF($O29="","",$O29*$P29) | T29: =IF($O29="","",$O29*$R29) | U29: =IF($O29="","",IF($O29=SUM($V29:$CB29),"OK","ERROR"))
A30: =IF(F30="","",_xlfn.CONCAT(_xlfn.IFNA(VLOOKUP(I30,Ruyxat!$F$2:$G$6,2,0),""),_xlfn.IFNA(VLOOKUP(F30,Ruyxat!$T$2:$U$16,2,0),""),TEXT(MID(A29,7,5)+1,"00000"))) | B30: 28 | C30: =Ruyxat!B84 -> Ветровка и юбка | E30: =_xlfn.IFNA(VLOOKUP(D30,[1]Ruyxat!$J$2:$L$601,2,0),"") | F30: =_xlfn.IFNA(VLOOKUP(D30,[1]Ruyxat!$J$2:$L$601,3,0),"") | M30: =IF(D30="","",TRIM(D30&" "&L30&" "&H30&" "&G30)) | R30: =IF($O30="","",ROUND($P30*(1+$Q30),-3)) | S30: =IF($O30="","",$O30*$P30) | T30: =IF($O30="","",$O30*$R30) | U30: =IF($O30="","",IF($O30=SUM($V30:$CB30),"OK","ERROR"))
A31: =IF(F31="","",_xlfn.CONCAT(_xlfn.IFNA(VLOOKUP(I31,Ruyxat!$F$2:$G$6,2,0),""),_xlfn.IFNA(VLOOKUP(F31,Ruyxat!$T$2:$U$16,2,0),""),TEXT(MID(A30,7,5)+1,"00000"))) | B31: 29 | C31: =Ruyxat!B85 -> Водолазка и сарафан | E31: =_xlfn.IFNA(VLOOKUP(D31,[1]Ruyxat!$J$2:$L$601,2,0),"") | F31: =_xlfn.IFNA(VLOOKUP(D31,[1]Ruyxat!$J$2:$L$601,3,0),"") | M31: =IF(D31="","",TRIM(D31&" "&L31&" "&H31&" "&G31)) | R31: =IF($O31="","",ROUND($P31*(1+$Q31),-3)) | S31: =IF($O31="","",$O31*$P31) | T31: =IF($O31="","",$O31*$R31) | U31: =IF($O31="","",IF($O31=SUM($V31:$CB31),"OK","ERROR"))

Sheet Tayyor
A1: Модель | B1: Вид товара | C1: Категория | D1: Группы | E1: Код модели | F1: Бренд | G1: Коллекция | H1: Сезон | I1: Размерный ряд | J1: Серия | K1: Закупочная цена | L1: Цена продажи | M1: Цвет | N1: Количество | O1: Описание | P1: Артикул | Q1: Наименование | R1: Код цвета
A2: A26TOP00405 | B2: Свитер | C2: Свитеры и кардиганы | D2: Одежда Топ | E2: 1M21241-1587 | F2: LIWALI | G2: AW26 | H2: Весна-Осень | I2: M-3XL | J2: 5 | K2: 150000 | L2: 175000 | M2: K.Bordo | N2: 30 | O2: варот замок мадел | P2: =_xlfn.CONCAT(A2,VLOOKUP(M2,Ruyxat!Z:AA,2,0)) -> A26TOP00405BRG | Q2: =IF(B2="","",TRIM(B2&" "&O2&" "&E2&" "&F2&" "&R2)) -> Свитер варот замок мадел 1M21241-1587 LIWALI
A3: A26TOP00405 | B3: Свитер | C3: Свитеры и кардиганы | D3: Одежда Топ | E3: 1M21241-1587 | F3: LIWALI | G3: AW26 | H3: Весна-Осень | I3: M-3XL | J3: 5 | K3: 150000 | L3: 175000 | M3: K.Lacivert | N3: 55 | O3: варот замок мадел | P3: =_xlfn.CONCAT(A3,VLOOKUP(M3,Ruyxat!Z:AA,2,0)) -> A26TOP00405DBL | Q3: =IF(B3="","",TRIM(B3&" "&O3&" "&E3&" "&F3&" "&R3)) -> Свитер варот замок мадел 1M21241-1587 LIWALI
A4: A26TOP00405 | B4: Свитер | C4: Свитеры и кардиганы | D4: Одежда Топ | E4: 1M21241-1587 | F4: LIWALI | G4: AW26 | H4: Весна-Осень | I4: M-3XL | J4: 5 | K4: 150000 | L4: 175000 | M4: K.Kahve | N4: 6 | O4: варот замок мадел | P4: =_xlfn.CONCAT(A4,VLOOKUP(M4,Ruyxat!Z:AA,2,0)) -> A26TOP00405DBR | Q4: =IF(B4="","",TRIM(B4&" "&O4&" "&E4&" "&F4&" "&R4)) -> Свитер варот замок мадел 1M21241-1587 LIWALI
A5: A26TOP00405 | B5: Свитер | C5: Свитеры и кардиганы | D5: Одежда Топ | E5: 1M21241-1587 | F5: LIWALI | G5: AW26 | H5: Весна-Осень | I5: M-3XL | J5: 5 | K5: 150000 | L5: 175000 | M5: Siyah | N5: 29 | O5: варот замок мадел | P5: =_xlfn.CONCAT(A5,VLOOKUP(M5,Ruyxat!Z:AA,2,0)) -> A26TOP00405BLK | Q5: =IF(B5="","",TRIM(B5&" "&O5&" "&E5&" "&F5&" "&R5)) -> Свитер варот замок мадел 1M21241-1587 LIWALI
A6: A26TOP00406 | B6: Свитер | C6: Свитеры и кардиганы | D6: Одежда Топ | E6: 1M21241-1485 | F6: LIWALI | G6: AW26 | H6: Весна-Осень | I6: M-3XL | J6: 5 | K6: 150000 | L6: 175000 | M6: K.Laci.P.Yesil | N6: 26 | O6: варот замок мелани | P6: =_xlfn.CONCAT(A6,VLOOKUP(M6,Ruyxat!Z:AA,2,0)) -> A26TOP00406DGR | Q6: =IF(B6="","",TRIM(B6&" "&O6&" "&E6&" "&F6&" "&R6)) -> Свитер варот замок мелани 1M21241-1485 LIWALI
A7: A26TOP00406 | B7: Свитер | C7: Свитеры и кардиганы | D7: Одежда Топ | E7: 1M21241-1485 | F7: LIWALI | G7: AW26 | H7: Весна-Осень | I7: M-3XL | J7: 5 | K7: 150000 | L7: 175000 | M7: K.Laci-Indigo | N7: 127 | O7: варот замок мелани | P7: =_xlfn.CONCAT(A7,VLOOKUP(M7,Ruyxat!Z:AA,2,0)) -> A26TOP00406DBN | Q7: =IF(B7="","",TRIM(B7&" "&O7&" "&E7&" "&F7&" "&R7)) -> Свитер варот замок мелани 1M21241-1485 LIWALI
A8: A26TOP00406 | B8: Свитер | C8: Свитеры и кардиганы | D8: Одежда Топ | E8: 1M21241-1485 | F8: LIWALI | G8: AW26 | H8: Весна-Осень | I8: M-3XL | J8: 5 | K8: 150000 | L8: 175000 | M8: K.Kahve.Kahve | N8: 27 | O8: варот замок мелани | P8: =_xlfn.CONCAT(A8,VLOOKUP(M8,Ruyxat!Z:AA,2,0)) -> A26TOP00406BRD | Q8: =IF(B8="","",TRIM(B8&" "&O8&" "&E8&" "&F8&" "&R8)) -> Свитер варот замок мелани 1M21241-1485 LIWALI
A9: A26TOP00406 | B9: Свитер | C9: Свитеры и кардиганы | D9: Одежда Топ | E9: 1M21241-1485 | F9: LIWALI | G9: AW26 | H9: Весна-Осень | I9: M-3XL | J9: 5 | K9: 150000 | L9: 175000 | M9: K.Laci.Kahve | N9: 52 | O9: варот замок мелани | P9: =_xlfn.CONCAT(A9,VLOOKUP(M9,Ruyxat!Z:AA,2,0)) -> A26TOP00406DBD | Q9: =IF(B9="","",TRIM(B9&" "&O9&" "&E9&" "&F9&" "&R9)) -> Свитер варот замок мелани 1M21241-1485 LIWALI
A10: A26TOP00406 | B10: Свитер | C10: Свитеры и кардиганы | D10: Одежда Топ | E10: 1M21241-1485 | F10: LIWALI | G10: AW26 | H10: Весна-Осень | I10: M-3XL | J10: 5 | K10: 150000 | L10: 175000 | M10: Vizon.K.Kahve | N10: 30 | O10: варот замок мелани | P10: =_xlfn.CONCAT(A10,VLOOKUP(M10,Ruyxat!Z:AA,2,0)) -> A26TOP00406BNR | Q10: =IF(B10="","",TRIM(B10&" "&O10&" "&E10&" "&F10&" "&R10)) -> Свитер варот замок мелани 1M21241-1485 LIWALI
A11: A26TOP00406 | B11: Свитер | C11: Свитеры и кардиганы | D11: Одежда Топ | E11: 1M21241-1485 | F11: LIWALI | G11: AW26 | H11: Весна-Осень | I11: M-3XL | J11: 5 | K11: 150000 | L11: 175000 | M11: K.Bej.Ekru | N11: 28 | O11: варот замок мелани | P11: =_xlfn.CONCAT(A11,VLOOKUP(M11,Ruyxat!Z:AA,2,0)) -> A26TOP00406DBM | Q11: =IF(B11="","",TRIM(B11&" "&O11&" "&E11&" "&F11&" "&R11)) -> Свитер варот замок мелани 1M21241-1485 LIWALI

Sheet Ruyxat
A1: Воротник | B1: Страна | C1: Застежка | D1: Образ Жизни | E1: Сезон | F1: Сезон коллекции | G1: Сезон для Арт. | I1: Кол-во | J1: Вид товара | K1: Категория | L1: Группа | N1: № | O1: Цвет | P1: Ткань | R1: Узор | T1: Группа | U1: Кодировка | V1: Значение | X1: № | Y1: Цвета | Z1: Турецкий | AA1: Кодировка | AB1: Значение | AC1: Цвета | AE1: RGB
A2: Стойка | B2: Узбекистан | C2: Без застежки | D2: Бейсик | E2: Всесезонный | F2: CONT | G2: CON | I2: =IF(ISNUMBER(SEARCH(Asosiy!$B$3,J2)),MAX($I$1:I1)+1,0) -> 1 | J2: Блузка | K2: Блузки и кофты | L2: Одежда Топ | N2: 54 | O2: Мультиколор | P2: Ангора | R2: Полоска | T2: Аксессуары | U2: ACC | V2: Accessories | X2: 1 | Y2: Белый | Z2: Beyaz | AA2: WHT | AB2: White | AD2: Beyaz | AE2: 255, 255, 255
A3: Круглый | B3: Китай | C3: Кнопка | D3: Классика | E3: Весна-Осень | F3: SS26 | G3: S26 | I3: =IF(ISNUMBER(SEARCH(Asosiy!$B$3,J3)),MAX($I$1:I2)+1,0) -> 2 | J3: Кофта | K3: Блузки и кофты | L3: Одежда Топ | N3: 1 | O3: Оранжевый | P3: Атлас | R3: Клетка | T3: Верхняя одежда | U3: OUT | V3: Outerwear | X3: =X2+1 -> 2 | Y3: Молочный | Z3: Ekru | AA3: MIL | AB3: Milk | AD3: Ekru | AE3: 248, 244, 227
A4: V-вырез | B4: Турция | C4: Замок | D4: Кэжуал | E4: Лето | F4: AW26 | G4: A26 | I4: =IF(ISNUMBER(SEARCH(Asosiy!$B$3,J4)),MAX($I$1:I3)+1,0) -> 3 | J4: Туника | K4: Блузки и кофты | L4: Одежда Топ | N4: 2 | O4: Кофейный | P4: Балоновый | R4: С принтом | T4: Нижнее белье | U4: UND | V4: Underwear | X4: =X3+1 -> 3 | Y4: Бежевый | Z4: Beige | AA4: BEI | AB4: Beige | AD4: Beige | AE4: 222, 184, 135
A5: Отложной | B5: Кыргызстан | C5: Пуговица | D5: Фэшн | E5: Зима | F5: SS25 | G5: S25 | I5: =IF(ISNUMBER(SEARCH(Asosiy!$B$3,J5)),MAX($I$1:I4)+1,0) -> 4 | J5: Платье | K5: Платья и сарафаны | L5: Одежда Топ | N5: 3 | O5: Золотистый | P5: Бамбук | R5: С вышивкой | T5: Обувь | U5: SHO | V5: Shoes | X5: =X4+1 -> 4 | Y5: Желтый | Z5: Sari | AA5: YEL | AB5: Yellow | AD5: Sari | AE5: 255, 255, 0
B6: Вьетнам | D6: Спорт | F6: AW25 | G6: A25 | I6: =IF(ISNUMBER(SEARCH(Asosiy!$B$3,J6)),MAX($I$1:I5)+1,0) -> 5 | J6: Сарафан | K6: Платья и сарафаны | L6: Одежда Топ | N6: 4 | O6: Цитрон | P6: Вельвет | R6: Однотонный | T6: Одежда Боттом | U6: BOT | V6: Bottom | X6: =X5+1 -> 5 | Y6: Оранжевый | Z6: Kiremit | AA6: ORA | AB6: Orange | AD6: Kiremit | AE6: 255, 165, 0
B7: Россия | D7: Школьный | I7: =IF(ISNUMBER(SEARCH(Asosiy!$B$3,J7)),MAX($I$1:I6)+1,0) -> 6 | J7: Рубашка | K7: Рубашки | L7: Одежда Топ | N7: 5 | O7: Молочный | P7: Велюр | R7: Горох | T7: Одежда комплект | U7: SET | V7: Set | X7: =X6+1 -> 6 | Y7: Красный | Z7: Bordo | AA7: RED | AB7: Red | AD7: Bordo | AE7: 255, 0, 0
B8: США | I8: =IF(ISNUMBER(SEARCH(Asosiy!$B$3,J8)),MAX($I$1:I7)+1,0) -> 7 | J8: Рубашка с длинными рукавами | K8: Рубашки | L8: Одежда Топ | N8: 6 | O8: Бежевый | P8: Вискоза | R8: Другое | T8: Одежда Топ | U8: TOP | V8: Top | X8: =X7+1 -> 7 | Y8: Бордовый | Z8: K.Bordo | AA8: BRG | AB8: Burgundy | AD8: K.Bordo | AE8: 128, 0, 32
B9: Белоруссия | I9: =IF(ISNUMBER(SEARCH(Asosiy!$B$3,J9)),MAX($I$1:I8)+1,0) -> 8 | J9: Водолазка | K9: Свитеры и кардиганы | L9: Одежда Топ | N9: 7 | O9: Бледно-серый | P9: Вязяный | R9: Животные | T9: Для новорождённых | U9: ANO | V9: Anonim | X9: =X8+1 -> 8 | Y9: Розовый | Z9: Pink | AA9: PNK | AB9: Pink | AD9: Pink | AE9: 255, 192, 203
B10: Великобритания | I10: =IF(ISNUMBER(SEARCH(Asosiy!$B$3,J10)),MAX($I$1:I9)+1,0) -> 9 | J10: Джемпер | K10: Свитеры и кардиганы | L10: Одежда Топ | N10: 8 | O10: Белый | P10: Гипюр | R10: Камуфляж | T10: Красота и уход | U10: ANO | V10: Anonim | X10: =X9+1 -> 9 | Y10: Фиолетовый | Z10: Violet | AA10: VIO | AB10: Purple | AD10: Violet | AE10: 128, 0, 128
B11: Италия | I11: =IF(ISNUMBER(SEARCH(Asosiy!$B$3,J11)),MAX($I$1:I10)+1,0) -> 10 | J11: Кардиган | K11: Свитеры и кардиганы | L11: Одежда Топ | N11: 9 | O11: Лимон лайм | P11: Деним | R11: Цветочный | T11: Текстиль | U11: ANO | V11: Anonim | X11: =X10+1 -> 10 | Y11: Салатовый | Z11: A.Yesil | AA11: LGN | AB11: Light Green | AD11: A.Yesil | AE11: 124, 252, 0
B12: ОАЭ | I12: =IF(ISNUMBER(SEARCH(Asosiy!$B$3,J12)),MAX($I$1:I11)+1,0) -> 11 | J12: Пуловер | K12: Свитеры и кардиганы | L12: Одежда Топ | N12: 10 | O12: Желтый | P12: Драп | R12: Леопардовый | T12: Личная гигиена | U12: ANO | V12: Anonim | X12: =X11+1 -> 11 | Y12: Зеленый | Z12: Yesil | AA12: GRN | AB12: Green | AD12: Yesil | AE12: 0, 128, 0
B13: Польша | I13: =IF(ISNUMBER(SEARCH(Asosiy!$B$3,J13)),MAX($I$1:I12)+1,0) -> 12 | J13: Свитер | K13: Свитеры и кардиганы | L13: Одежда Топ | N13: 11 | O13: Желто-зеленый | P13: Замша | R13: Рваность | T13: Стирки и уход за бельем | U13: ANO | V13: Anonim | X13: =X12+1 -> 12 | Y13: Темно-зеленый | Z13: P.Yesil | AA13: DGN | AB13: Dark Green | AD13: P.Yesil | AE13: 0, 100, 0
B14: Таиланд | I14: =IF(ISNUMBER(SEARCH(Asosiy!$B$3,J14)),MAX($I$1:I13)+1,0) -> 13 | J14: Свитер жилетка | K14: Свитеры и кардиганы | L14: Одежда Топ | N14: 12 | O14: Салатовый | P14: Интерлок | R14: Разное | T14: Гигиена и уход ребенка | U14: ANO | V14: Anonim | X14: =X13+1 -> 13 | Y14: Хаки | Z14: Haki | AA14: HKI | AB14: Khaki | AD14: Haki | AE14: 195, 176, 145
B15: Южная корея | I15: =IF(ISNUMBER(SEARCH(Asosiy!$B$3,J15)),MAX($I$1:I14)+1,0) -> 14 | J15: Свитер поло | K15: Свитеры и кардиганы | L15: Одежда Топ | N15: 13 | O15: Зеленый | P15: Кашемир | R15: Потертость | T15: Детское питание | U15: ANO | V15: Anonim | X15: =X14+1 -> 14 | Y15: Мята | Z15: Mint | AA15: MNT | AB15: Mint | AD15: Mint | AE15: 152, 255, 152
B16: Франция | I16: =IF(ISNUMBER(SEARCH(Asosiy!$B$3,J16)),MAX($I$1:I15)+1,0) -> 15 | J16: Американка | K16: Свитеры и кардиганы | L16: Одежда Топ | N16: 14 | O16: Бутылочно-зеленый | P16: Классическая ткань | R16: Бисер-камни | T16: Телефонные аксессуары | U16: ANO | V16: Anonim | X16: =X15+1 -> 15 | Y16: Бирюзовый | Z16: Turkuaz | AA16: TUR | AB16: Turquoise | AD16: Turkuaz | AE16: 64, 224, 208
I17: =IF(ISNUMBER(SEARCH(Asosiy!$B$3,J17)),MAX($I$1:I16)+1,0) -> 16 | J17: Олимпийка | K17: Толстовки и олимпийки | L17: Одежда Топ | N17: 15 | O17: Болотный | P17: Клеёнка | R17: Рисунок или ротация | X17: =X16+1 -> 16 | Y17: Голубой | Z17: Mavi | AA17: SKY | AB17: Sky Blue | AD17: Mavi | AE17: 135, 206, 235
I18: =IF(ISNUMBER(SEARCH(Asosiy!$B$3,J18)),MAX($I$1:I17)+1,0) -> 17 | J18: Толстовка | K18: Толстовки и олимпийки | L18: Одежда Топ | N18: 16 | O18: Оливковый | P18: Кожа | X18: =X17+1 -> 17 | Y18: Синий | Z18: Lacivert | AA18: NBL | AB18: Blue | AD18: Lacivert | AE18: 0, 102, 204
I19: =IF(ISNUMBER(SEARCH(Asosiy!$B$3,J19)),MAX($I$1:I18)+1,0) -> 18 | J19: Худи | K19: Толстовки и олимпийки | L19: Одежда Топ | N19: 17 | O19: Темно-зеленый | P19: Лайкра | X19: =X18+1 -> 18 | Y19: Индиго | Z19: Indigo | AA19: IND | AB19: Indigo | AD19: Indigo | AE19: 0, 0, 128
I20: =IF(ISNUMBER(SEARCH(Asosiy!$B$3,J20)),MAX($I$1:I19)+1,0) -> 19 | J20: Лонгслив | K20: Футболки и поло | L20: Одежда Топ | N20: 18 | O20: Ментоловый | P20: Махровая ткань | X20: =X19+1 -> 19 | Y20: Темно-синий | Z20: K.Lacivert | AA20: DBL | AB20: Dark Blue | AD20: K.Lacivert | AE20: 128, 128, 128
I21: =IF(ISNUMBER(SEARCH(Asosiy!$B$3,J21)),MAX($I$1:I20)+1,0) -> 20 | J21: Футболка поло | K21: Футболки и поло | L21: Одежда Топ | N21: 19 | O21: Коричневый | P21: Мех | X21: =X20+1 -> 20 | Y21: Серый | Z21: GRI | AA21: GRY | AB21: Gray | AD21: GRI | AE21: 64, 64, 64
B22: Отбор | I22: =IF(ISNUMBER(SEARCH(Asosiy!$B$3,J22)),MAX($I$1:I21)+1,0) -> 21 | J22: Поло с длинными рукавами | K22: Футболки и поло | L22: Одежда Топ | N22: 20 | O22: Каштан | P22: Начёс | X22: =X21+1 -> 21 | Y22: Темно-серый | Z22: K.GRI | AA22: DGY | AB22: Dark Gray | AD22: K.GRI | AE22: 139, 69, 19
A23: 1 | B23: =_xlfn.IFNA(VLOOKUP(A23,$I$2:$J$264,2,0),"") -> Блузка | I23: =IF(ISNUMBER(SEARCH(Asosiy!$B$3,J23)),MAX($I$1:I22)+1,0) -> 22 | J23: Футболка | K23: Футболки и поло | L23: Одежда Топ | N23: 21 | O23: Бледно-коричневый | P23: Плащевка | X23: =X22+1 -> 22 | Y23: Коричневый | Z23: Kahve | AA23: BRN | AB23: Brown | AD23: Kahve | AE23: 92, 51, 23
A24: 2 | B24: =_xlfn.IFNA(VLOOKUP(A24,$I$2:$J$264,2,0),"") -> Кофта | I24: =IF(ISNUMBER(SEARCH(Asosiy!$B$3,J24)),MAX($I$1:I23)+1,0) -> 23 | J24: Футболка безрукавка | K24: Футболки и поло | L24: Одежда Топ | N24: 22 | O24: Хаки | P24: Поролон | X24: =X23+1 -> 23 | Y24: Темно-коричневый | Z24: K.Kahve | AA24: DBR | AB24: Dark Brown | AD24: K.Kahve | AE24: 0, 0, 0
X25: =X24+1 -> 24 | Y25: Фиолетовый Синий | Z25: A.Lacivert | AA25: VBL | AB25: Violet Blue | AD25: A.Lacivert
X26: =X25+1 -> 25 | Y26: Тёмно-индиго | Z26: K.Indigo | AA26: DIN | AB26: Dark Indigo | AD26: K.Indigo
X27: =X26+1 -> 26 | Y27: Рыжий коричневый | Z27: Taba | AA27: TAN | AB27: Tan | AD27: Taba
X28: =X27+1 -> 27 | Y28: Визон | Z28: Vizon | AA28: MNK | AB28: Mink | AD28: Vizon
X29: =X28+1 -> 28 | Y29: Тёмный визон | Z29: K.Vizon | AA29: DMN | AB29: Dark Mink | AD29: K.Vizon
X30: =X29+1 -> 29 | Y30: Тёмно-бежевый | Z30: K.Bej | AA30: DBJ | AB30: Dark Beige | AD30: K.Bej
X31: =X30+1 -> 30 | Y31: Светло-бежевый | Z31: A.Bej | AA31: LBJ | AB31: Light Beige | AD31: A.Bej
X32: =X31+1 -> 31 | Y32: Антрасит | Z32: Antrasit | AA32: ANT | AB32: Anthracite | AD32: Antrasit
X33: =X32+1 -> 32 | Z33: Haki.Kahva | AA33: HRN
X34: =X33+1 -> 33 | Z34: K.Laci.Kahve | AA34: DBD
X35: =X34+1 -> 34 | Z35: P.Mavi.Melan | AA35: SKM
X36: =X35+1 -> 35 | Z36: A.Mavi | AA36: SAY
X37: =X36+1 -> 36 | Z37: A.Kiremit | AA37: ARO
X38: =X37+1 -> 37 | Z38: A.Haki | AA38: AHK
X39: =X38+1 -> 38 | Z39: M.Petrol | AA39: PTM
X40: =X39+1 -> 39 | Z40: Bordo K.Laci | AA40: BKL
...
